[2022-06-13 16:18:35,818] {taskinstance.py:1032} INFO - Dependencies all met for <TaskInstance: etl_third_dag.etl_second_task manual__2022-06-13T16:18:28.423222+00:00 [queued]>
[2022-06-13 16:18:36,376] {taskinstance.py:1032} INFO - Dependencies all met for <TaskInstance: etl_third_dag.etl_second_task manual__2022-06-13T16:18:28.423222+00:00 [queued]>
[2022-06-13 16:18:36,384] {taskinstance.py:1238} INFO - 
--------------------------------------------------------------------------------
[2022-06-13 16:18:36,384] {taskinstance.py:1239} INFO - Starting attempt 1 of 1
[2022-06-13 16:18:36,384] {taskinstance.py:1240} INFO - 
--------------------------------------------------------------------------------
[2022-06-13 16:18:36,661] {taskinstance.py:1259} INFO - Executing <Task(PythonOperator): etl_second_task> on 2022-06-13 16:18:28.423222+00:00
[2022-06-13 16:18:36,799] {standard_task_runner.py:52} INFO - Started process 485 to run task
[2022-06-13 16:18:36,934] {standard_task_runner.py:76} INFO - Running: ['***', 'tasks', 'run', 'etl_third_dag', 'etl_second_task', 'manual__2022-06-13T16:18:28.423222+00:00', '--job-id', '7', '--raw', '--subdir', 'DAGS_FOLDER/etl_third_run.py', '--cfg-path', '/tmp/tmpafffywkx', '--error-file', '/tmp/tmpbiawqnxm']
[2022-06-13 16:18:36,935] {standard_task_runner.py:77} INFO - Job 7: Subtask etl_second_task
[2022-06-13 16:18:38,603] {logging_mixin.py:109} INFO - Running <TaskInstance: etl_third_dag.etl_second_task manual__2022-06-13T16:18:28.423222+00:00 [running]> on host 4fc1de5525c3
[2022-06-13 16:18:40,348] {taskinstance.py:1426} INFO - Exporting the following env vars:
AIRFLOW_CTX_DAG_OWNER=Airflow
AIRFLOW_CTX_DAG_ID=etl_third_dag
AIRFLOW_CTX_TASK_ID=etl_second_task
AIRFLOW_CTX_EXECUTION_DATE=2022-06-13T16:18:28.423222+00:00
AIRFLOW_CTX_DAG_RUN_ID=manual__2022-06-13T16:18:28.423222+00:00
[2022-06-13 16:18:40,350] {logging_mixin.py:109} INFO - >>> Running 'run_etl' function. Logged at 2022-06-13 16:18:40.350109+00:00
[2022-06-13 16:18:40,350] {etl_first_run.py:18} INFO - >>> Running 'run_etl' function. Logged at 2022-06-13 16:18:40.350109+00:00
[2022-06-13 16:18:40,350] {etl_first_run.py:170} INFO - timer started
[2022-06-13 16:18:40,350] {logging_mixin.py:109} INFO - timer started
[2022-06-13 16:18:40,350] {logging_mixin.py:109} INFO - >>> Running 'connect_db' function. Logged at 2022-06-13 16:18:40.350756+00:00
[2022-06-13 16:18:40,350] {etl_first_run.py:18} INFO - >>> Running 'connect_db' function. Logged at 2022-06-13 16:18:40.350756+00:00
[2022-06-13 16:18:40,391] {etl_first_run.py:73} ERROR - (psycopg2.OperationalError) could not connect to server: Connection refused
	Is the server running on host "localhost" (127.0.0.1) and accepting
	TCP/IP connections on port 5432?
could not connect to server: Cannot assign requested address
	Is the server running on host "localhost" (::1) and accepting
	TCP/IP connections on port 5432?

(Background on this error at: http://sqlalche.me/e/13/e3q8)
[2022-06-13 16:18:40,421] {logging_mixin.py:109} INFO - >>> Function: 'connect_db' executed. Logged at 2022-06-13 16:18:40.350756+00:00
[2022-06-13 16:18:40,435] {etl_first_run.py:21} INFO - >>> Function: 'connect_db' executed. Logged at 2022-06-13 16:18:40.350756+00:00
[2022-06-13 16:18:40,436] {etl_first_run.py:177} ERROR - no db connection. Exiting
[2022-06-13 16:18:40,437] {logging_mixin.py:109} INFO - >>> Function: 'run_etl' executed. Logged at 2022-06-13 16:18:40.350109+00:00
[2022-06-13 16:18:40,437] {etl_first_run.py:21} INFO - >>> Function: 'run_etl' executed. Logged at 2022-06-13 16:18:40.350109+00:00
[2022-06-13 16:18:40,437] {python.py:175} INFO - Done. Returned value was: None
[2022-06-13 16:18:40,642] {taskinstance.py:1277} INFO - Marking task as SUCCESS. dag_id=etl_third_dag, task_id=etl_second_task, execution_date=20220613T161828, start_date=20220613T161835, end_date=20220613T161840
[2022-06-13 16:18:40,964] {local_task_job.py:154} INFO - Task exited with return code 0
[2022-06-13 16:18:41,273] {local_task_job.py:264} INFO - 0 downstream tasks scheduled from follow-on schedule check
