[2022-06-13 16:00:02,337] {taskinstance.py:1032} INFO - Dependencies all met for <TaskInstance: etl_second_dag.etl_second_task scheduled__2022-06-12T16:00:00+00:00 [queued]>
[2022-06-13 16:00:02,393] {taskinstance.py:1032} INFO - Dependencies all met for <TaskInstance: etl_second_dag.etl_second_task scheduled__2022-06-12T16:00:00+00:00 [queued]>
[2022-06-13 16:00:02,395] {taskinstance.py:1238} INFO - 
--------------------------------------------------------------------------------
[2022-06-13 16:00:02,396] {taskinstance.py:1239} INFO - Starting attempt 1 of 1
[2022-06-13 16:00:02,405] {taskinstance.py:1240} INFO - 
--------------------------------------------------------------------------------
[2022-06-13 16:00:02,448] {taskinstance.py:1259} INFO - Executing <Task(PythonOperator): etl_second_task> on 2022-06-12 16:00:00+00:00
[2022-06-13 16:00:02,485] {standard_task_runner.py:76} INFO - Running: ['***', 'tasks', 'run', 'etl_second_dag', 'etl_second_task', 'scheduled__2022-06-12T16:00:00+00:00', '--job-id', '3', '--raw', '--subdir', 'DAGS_FOLDER/etl_second_run.py', '--cfg-path', '/tmp/tmp1axlewml', '--error-file', '/tmp/tmpb89kq8l4']
[2022-06-13 16:00:02,493] {standard_task_runner.py:77} INFO - Job 3: Subtask etl_second_task
[2022-06-13 16:00:02,473] {standard_task_runner.py:52} INFO - Started process 568 to run task
[2022-06-13 16:00:02,714] {logging_mixin.py:109} INFO - Running <TaskInstance: etl_second_dag.etl_second_task scheduled__2022-06-12T16:00:00+00:00 [running]> on host 0529aec0d472
[2022-06-13 16:00:02,835] {taskinstance.py:1426} INFO - Exporting the following env vars:
AIRFLOW_CTX_DAG_OWNER=Airflow
AIRFLOW_CTX_DAG_ID=etl_second_dag
AIRFLOW_CTX_TASK_ID=etl_second_task
AIRFLOW_CTX_EXECUTION_DATE=2022-06-12T16:00:00+00:00
AIRFLOW_CTX_DAG_RUN_ID=scheduled__2022-06-12T16:00:00+00:00
[2022-06-13 16:00:02,837] {logging_mixin.py:109} INFO - >>> Running 'run_etl' function. Logged at 2022-06-13 16:00:02.837521+00:00
[2022-06-13 16:00:02,838] {etl_first_run.py:18} INFO - >>> Running 'run_etl' function. Logged at 2022-06-13 16:00:02.837521+00:00
[2022-06-13 16:00:02,838] {etl_first_run.py:169} INFO - timer started
[2022-06-13 16:00:02,838] {logging_mixin.py:109} INFO - timer started
[2022-06-13 16:00:02,838] {logging_mixin.py:109} INFO - >>> Running 'connect_db' function. Logged at 2022-06-13 16:00:02.838409+00:00
[2022-06-13 16:00:02,838] {etl_first_run.py:18} INFO - >>> Running 'connect_db' function. Logged at 2022-06-13 16:00:02.838409+00:00
[2022-06-13 16:00:02,839] {taskinstance.py:1700} ERROR - Task failed with exception
Traceback (most recent call last):
  File "/home/airflow/.local/lib/python3.7/site-packages/airflow/models/taskinstance.py", line 1329, in _run_raw_task
    self._execute_task_with_callbacks(context)
  File "/home/airflow/.local/lib/python3.7/site-packages/airflow/models/taskinstance.py", line 1455, in _execute_task_with_callbacks
    result = self._execute_task(context, self.task)
  File "/home/airflow/.local/lib/python3.7/site-packages/airflow/models/taskinstance.py", line 1511, in _execute_task
    result = execute_callable(context=context)
  File "/home/airflow/.local/lib/python3.7/site-packages/airflow/operators/python.py", line 174, in execute
    return_value = self.execute_callable()
  File "/home/airflow/.local/lib/python3.7/site-packages/airflow/operators/python.py", line 185, in execute_callable
    return self.python_callable(*self.op_args, **self.op_kwargs)
  File "/opt/airflow/dags/etl_first_run.py", line 19, in inner
    to_execute = fn(*args, **kwargs)
  File "/opt/airflow/dags/etl_first_run.py", line 172, in run_etl
    engine = connect_db()
  File "/opt/airflow/dags/etl_first_run.py", line 19, in inner
    to_execute = fn(*args, **kwargs)
  File "/opt/airflow/dags/etl_first_run.py", line 36, in connect_db
    import dotenv_values
ModuleNotFoundError: No module named 'dotenv_values'
[2022-06-13 16:00:02,888] {taskinstance.py:1277} INFO - Marking task as FAILED. dag_id=etl_second_dag, task_id=etl_second_task, execution_date=20220612T160000, start_date=20220613T160002, end_date=20220613T160002
[2022-06-13 16:00:02,953] {standard_task_runner.py:92} ERROR - Failed to execute job 3 for task etl_second_task
Traceback (most recent call last):
  File "/home/airflow/.local/lib/python3.7/site-packages/airflow/task/task_runner/standard_task_runner.py", line 85, in _start_by_fork
    args.func(args, dag=self.dag)
  File "/home/airflow/.local/lib/python3.7/site-packages/airflow/cli/cli_parser.py", line 48, in command
    return func(*args, **kwargs)
  File "/home/airflow/.local/lib/python3.7/site-packages/airflow/utils/cli.py", line 92, in wrapper
    return f(*args, **kwargs)
  File "/home/airflow/.local/lib/python3.7/site-packages/airflow/cli/commands/task_command.py", line 298, in task_run
    _run_task_by_selected_method(args, dag, ti)
  File "/home/airflow/.local/lib/python3.7/site-packages/airflow/cli/commands/task_command.py", line 107, in _run_task_by_selected_method
    _run_raw_task(args, ti)
  File "/home/airflow/.local/lib/python3.7/site-packages/airflow/cli/commands/task_command.py", line 184, in _run_raw_task
    error_file=args.error_file,
  File "/home/airflow/.local/lib/python3.7/site-packages/airflow/utils/session.py", line 70, in wrapper
    return func(*args, session=session, **kwargs)
  File "/home/airflow/.local/lib/python3.7/site-packages/airflow/models/taskinstance.py", line 1329, in _run_raw_task
    self._execute_task_with_callbacks(context)
  File "/home/airflow/.local/lib/python3.7/site-packages/airflow/models/taskinstance.py", line 1455, in _execute_task_with_callbacks
    result = self._execute_task(context, self.task)
  File "/home/airflow/.local/lib/python3.7/site-packages/airflow/models/taskinstance.py", line 1511, in _execute_task
    result = execute_callable(context=context)
  File "/home/airflow/.local/lib/python3.7/site-packages/airflow/operators/python.py", line 174, in execute
    return_value = self.execute_callable()
  File "/home/airflow/.local/lib/python3.7/site-packages/airflow/operators/python.py", line 185, in execute_callable
    return self.python_callable(*self.op_args, **self.op_kwargs)
  File "/opt/airflow/dags/etl_first_run.py", line 19, in inner
    to_execute = fn(*args, **kwargs)
  File "/opt/airflow/dags/etl_first_run.py", line 172, in run_etl
    engine = connect_db()
  File "/opt/airflow/dags/etl_first_run.py", line 19, in inner
    to_execute = fn(*args, **kwargs)
  File "/opt/airflow/dags/etl_first_run.py", line 36, in connect_db
    import dotenv_values
ModuleNotFoundError: No module named 'dotenv_values'
[2022-06-13 16:00:03,013] {local_task_job.py:154} INFO - Task exited with return code 1
[2022-06-13 16:00:03,164] {local_task_job.py:264} INFO - 0 downstream tasks scheduled from follow-on schedule check
[2022-06-13 16:11:57,854] {taskinstance.py:1032} INFO - Dependencies all met for <TaskInstance: etl_second_dag.etl_second_task scheduled__2022-06-12T16:00:00+00:00 [queued]>
[2022-06-13 16:11:57,929] {taskinstance.py:1032} INFO - Dependencies all met for <TaskInstance: etl_second_dag.etl_second_task scheduled__2022-06-12T16:00:00+00:00 [queued]>
[2022-06-13 16:11:57,930] {taskinstance.py:1238} INFO - 
--------------------------------------------------------------------------------
[2022-06-13 16:11:57,930] {taskinstance.py:1239} INFO - Starting attempt 1 of 1
[2022-06-13 16:11:57,930] {taskinstance.py:1240} INFO - 
--------------------------------------------------------------------------------
[2022-06-13 16:11:57,968] {taskinstance.py:1259} INFO - Executing <Task(PythonOperator): etl_second_task> on 2022-06-12 16:00:00+00:00
[2022-06-13 16:11:57,986] {standard_task_runner.py:52} INFO - Started process 293 to run task
[2022-06-13 16:11:58,013] {standard_task_runner.py:76} INFO - Running: ['***', 'tasks', 'run', 'etl_second_dag', 'etl_second_task', 'scheduled__2022-06-12T16:00:00+00:00', '--job-id', '6', '--raw', '--subdir', 'DAGS_FOLDER/etl_second_run.py', '--cfg-path', '/tmp/tmpcd8nzw8c', '--error-file', '/tmp/tmpcgj_imct']
[2022-06-13 16:11:58,014] {standard_task_runner.py:77} INFO - Job 6: Subtask etl_second_task
[2022-06-13 16:11:58,236] {logging_mixin.py:109} INFO - Running <TaskInstance: etl_second_dag.etl_second_task scheduled__2022-06-12T16:00:00+00:00 [running]> on host 4fc1de5525c3
[2022-06-13 16:11:58,357] {taskinstance.py:1426} INFO - Exporting the following env vars:
AIRFLOW_CTX_DAG_OWNER=Airflow
AIRFLOW_CTX_DAG_ID=etl_second_dag
AIRFLOW_CTX_TASK_ID=etl_second_task
AIRFLOW_CTX_EXECUTION_DATE=2022-06-12T16:00:00+00:00
AIRFLOW_CTX_DAG_RUN_ID=scheduled__2022-06-12T16:00:00+00:00
[2022-06-13 16:11:58,359] {logging_mixin.py:109} INFO - >>> Running 'run_etl' function. Logged at 2022-06-13 16:11:58.359220+00:00
[2022-06-13 16:11:58,359] {etl_first_run.py:18} INFO - >>> Running 'run_etl' function. Logged at 2022-06-13 16:11:58.359220+00:00
[2022-06-13 16:11:58,359] {etl_first_run.py:170} INFO - timer started
[2022-06-13 16:11:58,360] {logging_mixin.py:109} INFO - timer started
[2022-06-13 16:11:58,360] {logging_mixin.py:109} INFO - >>> Running 'connect_db' function. Logged at 2022-06-13 16:11:58.360326+00:00
[2022-06-13 16:11:58,360] {etl_first_run.py:18} INFO - >>> Running 'connect_db' function. Logged at 2022-06-13 16:11:58.360326+00:00
[2022-06-13 16:11:58,363] {etl_first_run.py:73} ERROR - (psycopg2.OperationalError) could not connect to server: Connection refused
	Is the server running on host "localhost" (127.0.0.1) and accepting
	TCP/IP connections on port 5432?
could not connect to server: Cannot assign requested address
	Is the server running on host "localhost" (::1) and accepting
	TCP/IP connections on port 5432?

(Background on this error at: http://sqlalche.me/e/13/e3q8)
[2022-06-13 16:11:58,363] {logging_mixin.py:109} INFO - >>> Function: 'connect_db' executed. Logged at 2022-06-13 16:11:58.360326+00:00
[2022-06-13 16:11:58,365] {etl_first_run.py:21} INFO - >>> Function: 'connect_db' executed. Logged at 2022-06-13 16:11:58.360326+00:00
[2022-06-13 16:11:58,365] {etl_first_run.py:177} ERROR - no db connection. Exiting
[2022-06-13 16:11:58,365] {logging_mixin.py:109} INFO - >>> Function: 'run_etl' executed. Logged at 2022-06-13 16:11:58.359220+00:00
[2022-06-13 16:11:58,366] {etl_first_run.py:21} INFO - >>> Function: 'run_etl' executed. Logged at 2022-06-13 16:11:58.359220+00:00
[2022-06-13 16:11:58,366] {python.py:175} INFO - Done. Returned value was: None
[2022-06-13 16:11:58,388] {taskinstance.py:1277} INFO - Marking task as SUCCESS. dag_id=etl_second_dag, task_id=etl_second_task, execution_date=20220612T160000, start_date=20220613T161157, end_date=20220613T161158
[2022-06-13 16:11:58,442] {local_task_job.py:154} INFO - Task exited with return code 0
[2022-06-13 16:11:58,525] {local_task_job.py:264} INFO - 0 downstream tasks scheduled from follow-on schedule check
