[2022-06-13 16:11:39,544] {taskinstance.py:1032} INFO - Dependencies all met for <TaskInstance: etl_second_dag.etl_second_task manual__2022-06-13T16:11:35.670196+00:00 [queued]>
[2022-06-13 16:11:39,565] {taskinstance.py:1032} INFO - Dependencies all met for <TaskInstance: etl_second_dag.etl_second_task manual__2022-06-13T16:11:35.670196+00:00 [queued]>
[2022-06-13 16:11:39,566] {taskinstance.py:1238} INFO - 
--------------------------------------------------------------------------------
[2022-06-13 16:11:39,566] {taskinstance.py:1239} INFO - Starting attempt 1 of 1
[2022-06-13 16:11:39,566] {taskinstance.py:1240} INFO - 
--------------------------------------------------------------------------------
[2022-06-13 16:11:39,586] {taskinstance.py:1259} INFO - Executing <Task(PythonOperator): etl_second_task> on 2022-06-13 16:11:35.670196+00:00
[2022-06-13 16:11:39,600] {standard_task_runner.py:52} INFO - Started process 282 to run task
[2022-06-13 16:11:39,626] {standard_task_runner.py:76} INFO - Running: ['***', 'tasks', 'run', 'etl_second_dag', 'etl_second_task', 'manual__2022-06-13T16:11:35.670196+00:00', '--job-id', '5', '--raw', '--subdir', 'DAGS_FOLDER/etl_second_run.py', '--cfg-path', '/tmp/tmpbz62m275', '--error-file', '/tmp/tmpzlk391py']
[2022-06-13 16:11:39,627] {standard_task_runner.py:77} INFO - Job 5: Subtask etl_second_task
[2022-06-13 16:11:39,751] {logging_mixin.py:109} INFO - Running <TaskInstance: etl_second_dag.etl_second_task manual__2022-06-13T16:11:35.670196+00:00 [running]> on host 4fc1de5525c3
[2022-06-13 16:11:39,863] {taskinstance.py:1426} INFO - Exporting the following env vars:
AIRFLOW_CTX_DAG_OWNER=Airflow
AIRFLOW_CTX_DAG_ID=etl_second_dag
AIRFLOW_CTX_TASK_ID=etl_second_task
AIRFLOW_CTX_EXECUTION_DATE=2022-06-13T16:11:35.670196+00:00
AIRFLOW_CTX_DAG_RUN_ID=manual__2022-06-13T16:11:35.670196+00:00
[2022-06-13 16:11:39,867] {logging_mixin.py:109} INFO - >>> Running 'run_etl' function. Logged at 2022-06-13 16:11:39.867231+00:00
[2022-06-13 16:11:39,867] {etl_first_run.py:18} INFO - >>> Running 'run_etl' function. Logged at 2022-06-13 16:11:39.867231+00:00
[2022-06-13 16:11:39,867] {etl_first_run.py:170} INFO - timer started
[2022-06-13 16:11:39,868] {logging_mixin.py:109} INFO - timer started
[2022-06-13 16:11:39,868] {logging_mixin.py:109} INFO - >>> Running 'connect_db' function. Logged at 2022-06-13 16:11:39.868392+00:00
[2022-06-13 16:11:39,868] {etl_first_run.py:18} INFO - >>> Running 'connect_db' function. Logged at 2022-06-13 16:11:39.868392+00:00
[2022-06-13 16:11:39,870] {etl_first_run.py:73} ERROR - (psycopg2.OperationalError) could not connect to server: Connection refused
	Is the server running on host "localhost" (127.0.0.1) and accepting
	TCP/IP connections on port 5432?
could not connect to server: Cannot assign requested address
	Is the server running on host "localhost" (::1) and accepting
	TCP/IP connections on port 5432?

(Background on this error at: http://sqlalche.me/e/13/e3q8)
[2022-06-13 16:11:39,871] {logging_mixin.py:109} INFO - >>> Function: 'connect_db' executed. Logged at 2022-06-13 16:11:39.868392+00:00
[2022-06-13 16:11:39,871] {etl_first_run.py:21} INFO - >>> Function: 'connect_db' executed. Logged at 2022-06-13 16:11:39.868392+00:00
[2022-06-13 16:11:39,871] {etl_first_run.py:177} ERROR - no db connection. Exiting
[2022-06-13 16:11:39,871] {logging_mixin.py:109} INFO - >>> Function: 'run_etl' executed. Logged at 2022-06-13 16:11:39.867231+00:00
[2022-06-13 16:11:39,871] {etl_first_run.py:21} INFO - >>> Function: 'run_etl' executed. Logged at 2022-06-13 16:11:39.867231+00:00
[2022-06-13 16:11:39,871] {python.py:175} INFO - Done. Returned value was: None
[2022-06-13 16:11:39,888] {taskinstance.py:1277} INFO - Marking task as SUCCESS. dag_id=etl_second_dag, task_id=etl_second_task, execution_date=20220613T161135, start_date=20220613T161139, end_date=20220613T161139
[2022-06-13 16:11:39,926] {local_task_job.py:154} INFO - Task exited with return code 0
[2022-06-13 16:11:39,999] {local_task_job.py:264} INFO - 0 downstream tasks scheduled from follow-on schedule check
