[2022-06-13 15:53:31,424] {taskinstance.py:1032} INFO - Dependencies all met for <TaskInstance: etl_second_dag.etl_second_task manual__2022-06-13T15:53:27.422514+00:00 [queued]>
[2022-06-13 15:53:31,449] {taskinstance.py:1032} INFO - Dependencies all met for <TaskInstance: etl_second_dag.etl_second_task manual__2022-06-13T15:53:27.422514+00:00 [queued]>
[2022-06-13 15:53:31,450] {taskinstance.py:1238} INFO - 
--------------------------------------------------------------------------------
[2022-06-13 15:53:31,450] {taskinstance.py:1239} INFO - Starting attempt 1 of 1
[2022-06-13 15:53:31,450] {taskinstance.py:1240} INFO - 
--------------------------------------------------------------------------------
[2022-06-13 15:53:31,482] {taskinstance.py:1259} INFO - Executing <Task(PythonOperator): etl_second_task> on 2022-06-13 15:53:27.422514+00:00
[2022-06-13 15:53:31,497] {standard_task_runner.py:52} INFO - Started process 358 to run task
[2022-06-13 15:53:31,531] {standard_task_runner.py:76} INFO - Running: ['***', 'tasks', 'run', 'etl_second_dag', 'etl_second_task', 'manual__2022-06-13T15:53:27.422514+00:00', '--job-id', '2', '--raw', '--subdir', 'DAGS_FOLDER/etl_second_run.py', '--cfg-path', '/tmp/tmpag9e1ytn', '--error-file', '/tmp/tmpfit3mdfg']
[2022-06-13 15:53:31,533] {standard_task_runner.py:77} INFO - Job 2: Subtask etl_second_task
[2022-06-13 15:53:31,770] {logging_mixin.py:109} INFO - Running <TaskInstance: etl_second_dag.etl_second_task manual__2022-06-13T15:53:27.422514+00:00 [running]> on host 0529aec0d472
[2022-06-13 15:53:31,969] {taskinstance.py:1426} INFO - Exporting the following env vars:
AIRFLOW_CTX_DAG_OWNER=Airflow
AIRFLOW_CTX_DAG_ID=etl_second_dag
AIRFLOW_CTX_TASK_ID=etl_second_task
AIRFLOW_CTX_EXECUTION_DATE=2022-06-13T15:53:27.422514+00:00
AIRFLOW_CTX_DAG_RUN_ID=manual__2022-06-13T15:53:27.422514+00:00
[2022-06-13 15:53:31,971] {logging_mixin.py:109} INFO - >>> Running 'run_etl' function. Logged at 2022-06-13 15:53:31.971019+00:00
[2022-06-13 15:53:31,971] {etl_first_run.py:18} INFO - >>> Running 'run_etl' function. Logged at 2022-06-13 15:53:31.971019+00:00
[2022-06-13 15:53:31,971] {etl_first_run.py:169} INFO - timer started
[2022-06-13 15:53:31,972] {logging_mixin.py:109} INFO - timer started
[2022-06-13 15:53:31,972] {logging_mixin.py:109} INFO - >>> Running 'connect_db' function. Logged at 2022-06-13 15:53:31.972575+00:00
[2022-06-13 15:53:31,972] {etl_first_run.py:18} INFO - >>> Running 'connect_db' function. Logged at 2022-06-13 15:53:31.972575+00:00
[2022-06-13 15:53:31,974] {taskinstance.py:1700} ERROR - Task failed with exception
Traceback (most recent call last):
  File "/home/airflow/.local/lib/python3.7/site-packages/airflow/models/taskinstance.py", line 1329, in _run_raw_task
    self._execute_task_with_callbacks(context)
  File "/home/airflow/.local/lib/python3.7/site-packages/airflow/models/taskinstance.py", line 1455, in _execute_task_with_callbacks
    result = self._execute_task(context, self.task)
  File "/home/airflow/.local/lib/python3.7/site-packages/airflow/models/taskinstance.py", line 1511, in _execute_task
    result = execute_callable(context=context)
  File "/home/airflow/.local/lib/python3.7/site-packages/airflow/operators/python.py", line 174, in execute
    return_value = self.execute_callable()
  File "/home/airflow/.local/lib/python3.7/site-packages/airflow/operators/python.py", line 185, in execute_callable
    return self.python_callable(*self.op_args, **self.op_kwargs)
  File "/opt/airflow/dags/etl_first_run.py", line 19, in inner
    to_execute = fn(*args, **kwargs)
  File "/opt/airflow/dags/etl_first_run.py", line 172, in run_etl
    engine = connect_db()
  File "/opt/airflow/dags/etl_first_run.py", line 19, in inner
    to_execute = fn(*args, **kwargs)
  File "/opt/airflow/dags/etl_first_run.py", line 36, in connect_db
    import dotenv_values
ModuleNotFoundError: No module named 'dotenv_values'
[2022-06-13 15:53:32,024] {taskinstance.py:1277} INFO - Marking task as FAILED. dag_id=etl_second_dag, task_id=etl_second_task, execution_date=20220613T155327, start_date=20220613T155331, end_date=20220613T155332
[2022-06-13 15:53:32,173] {standard_task_runner.py:92} ERROR - Failed to execute job 2 for task etl_second_task
Traceback (most recent call last):
  File "/home/airflow/.local/lib/python3.7/site-packages/airflow/task/task_runner/standard_task_runner.py", line 85, in _start_by_fork
    args.func(args, dag=self.dag)
  File "/home/airflow/.local/lib/python3.7/site-packages/airflow/cli/cli_parser.py", line 48, in command
    return func(*args, **kwargs)
  File "/home/airflow/.local/lib/python3.7/site-packages/airflow/utils/cli.py", line 92, in wrapper
    return f(*args, **kwargs)
  File "/home/airflow/.local/lib/python3.7/site-packages/airflow/cli/commands/task_command.py", line 298, in task_run
    _run_task_by_selected_method(args, dag, ti)
  File "/home/airflow/.local/lib/python3.7/site-packages/airflow/cli/commands/task_command.py", line 107, in _run_task_by_selected_method
    _run_raw_task(args, ti)
  File "/home/airflow/.local/lib/python3.7/site-packages/airflow/cli/commands/task_command.py", line 184, in _run_raw_task
    error_file=args.error_file,
  File "/home/airflow/.local/lib/python3.7/site-packages/airflow/utils/session.py", line 70, in wrapper
    return func(*args, session=session, **kwargs)
  File "/home/airflow/.local/lib/python3.7/site-packages/airflow/models/taskinstance.py", line 1329, in _run_raw_task
    self._execute_task_with_callbacks(context)
  File "/home/airflow/.local/lib/python3.7/site-packages/airflow/models/taskinstance.py", line 1455, in _execute_task_with_callbacks
    result = self._execute_task(context, self.task)
  File "/home/airflow/.local/lib/python3.7/site-packages/airflow/models/taskinstance.py", line 1511, in _execute_task
    result = execute_callable(context=context)
  File "/home/airflow/.local/lib/python3.7/site-packages/airflow/operators/python.py", line 174, in execute
    return_value = self.execute_callable()
  File "/home/airflow/.local/lib/python3.7/site-packages/airflow/operators/python.py", line 185, in execute_callable
    return self.python_callable(*self.op_args, **self.op_kwargs)
  File "/opt/airflow/dags/etl_first_run.py", line 19, in inner
    to_execute = fn(*args, **kwargs)
  File "/opt/airflow/dags/etl_first_run.py", line 172, in run_etl
    engine = connect_db()
  File "/opt/airflow/dags/etl_first_run.py", line 19, in inner
    to_execute = fn(*args, **kwargs)
  File "/opt/airflow/dags/etl_first_run.py", line 36, in connect_db
    import dotenv_values
ModuleNotFoundError: No module named 'dotenv_values'
[2022-06-13 15:53:32,316] {local_task_job.py:154} INFO - Task exited with return code 1
[2022-06-13 15:53:32,413] {local_task_job.py:264} INFO - 0 downstream tasks scheduled from follow-on schedule check
